/cvmfs/icecube.opensciencegrid.org/py2-v3.0.1/RHEL_7_x86_64/lib/python2.7/site-packages/astropy/config/configuration.py:541: ConfigurationMissingWarning: Configuration defaults will be used due to OSError:Could not find unix home directory to search for astropy config dir on None
  warn(ConfigurationMissingWarning(msg))
/cvmfs/icecube.opensciencegrid.org/py2-v3.0.1/RHEL_7_x86_64/lib/python2.7/site-packages/scipy/stats/_distn_infrastructure.py:2300: RuntimeWarning: Mean of empty slice.
  muhat = tmp.mean()
/cvmfs/icecube.opensciencegrid.org/py2-v3.0.1/RHEL_7_x86_64/lib/python2.7/site-packages/numpy/core/_methods.py:80: RuntimeWarning: invalid value encountered in double_scalars
  ret = ret.dtype.type(ret / rcount)
/cvmfs/icecube.opensciencegrid.org/py2-v3.0.1/RHEL_7_x86_64/lib/python2.7/site-packages/scipy/stats/_distn_infrastructure.py:2301: RuntimeWarning: Degrees of freedom <= 0 for slice
  mu2hat = tmp.var()
/cvmfs/icecube.opensciencegrid.org/py2-v3.0.1/RHEL_7_x86_64/lib/python2.7/site-packages/numpy/core/_methods.py:105: RuntimeWarning: invalid value encountered in true_divide
  arrmean, rcount, out=arrmean, casting='unsafe', subok=False)
/cvmfs/icecube.opensciencegrid.org/py2-v3.0.1/RHEL_7_x86_64/lib/python2.7/site-packages/numpy/core/_methods.py:127: RuntimeWarning: invalid value encountered in double_scalars
  ret = ret.dtype.type(ret / rcount)
warning: Chi2TSD() could not find good chi2 fit
Traceback (most recent call last):
  File "Python_Elisa/sens_ext5_llhextNone_cutnsigNone_sigsubFalse.py", line 80, in <module>
    sens_5 = [get_sens(ana7,ra=0,sindec=d,ext=np.radians(5),llh_ext=None, cut_n_sigma=None, gamma=2, sigsub=False) for d in sindec_array]
  File "Python_Elisa/sens_ext5_llhextNone_cutnsigNone_sigsubFalse.py", line 63, in get_sens
    sens = tr.find_n_sig(bg.median(),0.9,batch_size=batch_size,max_batch_size=1000,tol=0.03, coverage=2)
  File "/mnt/lfs3/user/drysewyk/software/external/csky/csky/dists.py", line 188, in median
    return float (self.isf (.5 + eps, fit=fit))
  File "/mnt/lfs3/user/drysewyk/software/external/csky/csky/dists.py", line 177, in isf
    self.values[ii]),
IndexError: index 0 is out of bounds for axis 0 with size 0
